Workbook
Name Slicer_Executive_name: #N/A

Sheet Dashboard
B1: BRANCH DASHBOARD
B4: TOTAL TARGET | F4: Agg.revenue | J4: Invoice sales | N4: Percenatge of achievement | R4: Meetings in current year
B7: ="₹ "&TEXT('Pivot table'!D4,"0,000,000") -> ₹ 52,076,359 | F7: ="₹ "& TEXT('Pivot table'!C8, "0,000,000") -> ₹ 33,891,101 | J7: =" ₹"&TEXT(GETPIVOTDATA("[Measures].[Sum of Amount 3]",'Pivot table'!$A$11),"0,000,000") -> ₹11,056,587 | N7: =" "&'Pivot table'!B15&"%" -> 86% | R7: =" "&GETPIVOTDATA("[Measures].[Count of meeting_date]",'Pivot table'!$A$19) -> 31
B10: ='Pivot table'!E26&" performance across KPI's" -> Abhinav Shivam performance across KPI's
S13: ="Top in open opportunity: "&_xlfn.XLOOKUP(S15,'Pivot table'!Q18:Q30,'Pivot table'!N18:N30) -> Top in open opportunity: Mark
S15: =MAX('Pivot table'!Q21:Q30) -> 1284500
S18: ="No of invoice by "&'Pivot table'!$E$26 -> No of invoice by Abhinav Shivam
S20: =IF(ISBLANK('Pivot table'!G4)=TRUE, " ",IFERROR(VLOOKUP(RIGHT(S18,LEN(S18)-SEARCH(" ",S18,SEARCH(" ",S18,SEARCH(" ",S18,SEARCH(" ",S18)+1)+1)+1)),'Pivot table'!G:H,2,0),"Record not found")) -> 10
B21: ="Renewal for " & 'Pivot table'!E26 -> Renewal for Abhinav Shivam
S22: ="Yearly meeting count for "&'Pivot table'!E26 -> Yearly meeting count for Abhinav Shivam
B23: Achieve | C23: =IFERROR(VLOOKUP('Pivot table'!E26,'Pivot table'!L25:M36,2,0)," No record found") -> 109812.12
B24: Target | C24: =VLOOKUP('Pivot table'!E26,'Pivot table'!O3:Q12,3,0) -> 1289000 | S24: =VLOOKUP('Pivot table'!E26,'Pivot table'!G20:H20,2,0) -> 7
B25: New | C25: =C24-C23 -> 1179187.9
S26: Open Opportunities
B27: ="Cross Sell for "&'Pivot table'!E26 -> Cross Sell for Abhinav Shivam
S28: =" "&GETPIVOTDATA("[Measures].[Count of stage]",'Pivot table'!$A$22,"[gcrm_opportunity_202001231041].[stage]","[gcrm_opportunity_202001231041].[stage].&[Qualify Opportunity]")+GETPIVOTDATA("[Measures].[Count of stage]",'Pivot table'!$A$22,"[gcrm_opportunity_202001231041].[stage]","[gcrm_opportunity_202001231041].[stage].&[Propose Solution]") -> 44
B29: Achieve | C29: =IFERROR(VLOOKUP('Pivot table'!E26,'Pivot table'!L6:M15,2,0)," No record found") -> 206294.29
B30: Target | C30: =VLOOKUP('Pivot table'!E26,'Pivot table'!O3:R12,4,0) -> 129000 | S30: Closed opportunities
B31: New | C31: =C30-C29 -> -77294.29
S32: =" "&GETPIVOTDATA("[Measures].[Count of stage]",'Pivot table'!$A$22,"[gcrm_opportunity_202001231041].[stage]","[gcrm_opportunity_202001231041].[stage].&[Negotiate]") -> 5
B33: ="New for "& 'Pivot table'!E26 -> New for Abhinav Shivam
S34: Conversion ratio
B35: Achieve | C35: =IFERROR(VLOOKUP('Pivot table'!E26,'Pivot table'!L17:M23,2,0),"No record found") -> 642953.46
B36: Target | C36: =IFERROR(VLOOKUP('Pivot table'!E26,'Pivot table'!O2:P12,2,0), " ") -> 129902 | S36: =""& ROUND(GETPIVOTDATA("[Measures].[Count of stage]",'Pivot table'!$A$22,"[gcrm_opportunity_202001231041].[stage]","[gcrm_opportunity_202001231041].[stage].&[Negotiate]")/GETPIVOTDATA("[Measures].[Count of stage]",'Pivot table'!$A$22),2)*100&"%" -> 10%
B37: New | G37: =RIGHT(C3)

Sheet Pivot table
L1: Achieve | O1: Budget
A2: Branch level | D2: Table 1 | G2: Employee level | L2: Row Labels | M2: Sum of Amount | O2: Row Labels | P2: Sum of New Budget | Q2: Sum of Renewal Budget | R2: Sum of Cross sell bugdet
A3: Sum of New Budget | B3: Sum of Renewal Budget | C3: Sum of Cross sell bugdet | F3: Pivot table 8 | G3: Row Labels | H3: Count of invoice_number | L3: (blank) | O3: Abhinav Shivam | P3: 129902 | Q3: 1289000 | R3: 129000 | T3: Cross sale | U3: =SUM(M6:M15) -> 11468322
A4: 19673793 | B4: 12319455 | C4: 20083111 | D4: =A4+B4+C4 -> 52076359 | G4: Abhinav Shivam | H4: 10 | L4: Vididt Saha | M4: 1558.76 | O4: Animesh Rawat | P4: 1278023 | Q4: 12900 | R4: 12365300 | T4: New | U4: =SUM(M17:M23) -> 3431629.3
G5: Animesh Rawat | H5: 20 | L5: Cross Sell | O5: Gilbert | P5: 1000000 | Q5: 1010000 | R5: 500000 | T5: Renewal | U5: =SUM(M25:M36) -> 18475059
A6: Brokerage | B6: Fee | G6: Gilbert | H6: 57 | L6: Abhinav Shivam | M6: 206294.29 | O6: Juli | P6: 1250000 | Q6: 750000 | R6: 3500000 | U6: =SUM(U3:U5) -> 33375010
A7: Sum of Amount | C7: Table 2 | G7: Juli | H7: 22 | L7: Animesh Rawat | M7: 593114.78 | O7: Ketan Jain | P7: 500000 | Q7: 500000 | R7: 1250000
A8: 514531 | C8: =GETPIVOTDATA("[Measures].[Sum of Amount 2]",$A$7)+33376569.99 -> 33891101 | G8: Ketan Jain | H8: 36 | L8: Juli | M8: 417 | O8: Kumar Jha | P8: 1345000 | Q8: 1298673 | R8: 170034 | T8: Cross sale | U8: =U3/U$6 -> 0.34362003
G9: Mark | H9: 3 | L9: Ketan Jain | M9: 28087.5 | O9: Manish Sharma | P9: 1350000 | Q9: 750000 | R9: 750000 | T9: New | U9: =U4/U$6 -> 0.10282032
A10: Invoice | G10: Vinay | H10: 23 | L10: Manish Sharma | M10: 36357.09 | O10: Mark | P10: 19888 | Q10: 198882 | R10: 128777 | T10: Renewal | U10: =U5/U$6 -> 0.55355965
A11: Sum of Amount | C11: Table 3 | G11: (blank) | H11: 27 | L11: Mark | M11: 63872.4 | O11: Vidit Shah | P11: 12888 | Q11: 5010000 | R11: 1040000
A12: 11056587 | G12: Grand Total | H12: 198 | L12: Raju Kumar | M12: 821261.22 | O12: Vinay | P12: 12788092 | Q12: 1500000 | R12: 250000
L13: Shivani Sharma | M13: 22047 | O13: Grand Total | P13: 19673793 | Q13: 12319455 | R13: 20083111
A14: Percentage of Achievement | L14: Vididt Saha | M14: 1129398.1
A15: =(C8+GETPIVOTDATA("[Measures].[Sum of Amount 3]",$A$11))/D4 -> 0.86311119 | B15: =ROUND(A15,2)*100 -> 86 | L15: Vinay | M15: 8567472.7
L16: New | O16: Stage funnel by revenue | R16: Number of meeting by Executive
A17: meeting_date | B17: (Multiple Items) | C17: Table 4 | L17: Abhinav Shivam | M17: 642953.46 | O17: Row Labels | P17: Sum of revenue_amount | R17: Row Labels | S17: Count of global_attendees
L18: Animesh Rawat | M18: 55107.13 | O18: Animesh Rawat | R18: Abhinav Shivam | S18: 7
A19: Count of meeting_date | C19: Table 4 | F19: Pivot table 10 | G19: Row Labels | H19: Count of meeting_date | L19: Juli | M19: 150230.05 | O19: Negotiate | P19: 800000 | R19: Animesh Rawat | S19: 4 | U19: Abhinav Shivam | V19: 7
A20: 31 | G20: Abhinav Shivam | H20: 7 | L20: Ketan Jain | M20: 743804.31 | N20: Animesh Rawat | O20: Propose Solution | P20: 60000 | R20: Gilbert | S20: 3 | U20: Vinay | V20: 5
G21: Animesh Rawat | H21: 4 | L21: Raju Kumar | M21: 100000 | N21: Animesh Rawat | O21: Qualify Opportunity | P21: 1025000 | Q21: =GETPIVOTDATA("[Measures].[Sum of revenue_amount]",$O$17,"[gcrm_opportunity_202001231041].[Account Executive]","[gcrm_opportunity_202001231041].[Account Executive].&[Animesh Rawat]","[gcrm_opportunity_202001231041].[stage]","[gcrm_opportunity_202001231041].[stage].&[Qualify Opportunity]")+GETPIVOTDATA("[Measures].[Sum of revenue_amount]",$O$17,"[gcrm_opportunity_202001231041].[Account Executive]","[gcrm_opportunity_202001231041].[Account Executive].&[Animesh Rawat]","[gcrm_opportunity_202001231041].[stage]","[gcrm_opportunity_202001231041].[stage].&[Propose Solution]") -> 1085000 | R21: Ketan Jain | S21: 4 | U21: Shivani Sharma | V21: 4
A22: Row Labels | B22: Count of stage | C22: Table 5 | G22: Gilbert | H22: 3 | I22: =IFERROR(VLOOKUP(E26,L17:M23,2,0),"No record found") -> 642953.46 | L22: Vididt Saha | M22: 328465.82 | N22: Ketan Jain | O22: Ketan Jain | R22: Manish Sharma | S22: 3 | U22: Animesh Rawat | V22: 4
A23: Negotiate | B23: 5 | G23: Ketan Jain | H23: 4 | I23: =IFERROR(VLOOKUP(E26,L6:M15,2,0),"No record found") -> 206294.29 | L23: Vinay | M23: 1411068.5 | N23: Ketan Jain | O23: Qualify Opportunity | P23: 1530000 | R23: Mark | S23: 2 | U23: Ketan Jain | V23: 4
A24: Propose Solution | B24: 2 | G24: Manish Sharma | H24: 3 | L24: Renewal | N24: Mark | O24: Mark | R24: Raju Kumar | S24: 2 | U24: Gilbert | V24: 3
A25: Qualify Opportunity | B25: 42 | D25: Pivot table 7 | E25: Row Labels | G25: Mark | H25: 2 | L25: Abhinav Shivam | M25: 109812.12 | N25: Mark | O25: Negotiate | P25: 99000 | R25: Shivani Sharma | S25: 4 | U25: Manish Sharma | V25: 3
A26: Grand Total | B26: 49 | D26: Employee selector | E26: Abhinav Shivam | G26: Raju Kumar | H26: 2 | L26: Animesh Rawat | M26: 6413431.4 | N26: Mark | O26: Qualify Opportunity | P26: 1284500 | Q26: =GETPIVOTDATA("[Measures].[Sum of revenue_amount]",$O$17,"[gcrm_opportunity_202001231041].[Account Executive]","[gcrm_opportunity_202001231041].[Account Executive].&[Mark]","[gcrm_opportunity_202001231041].[stage]","[gcrm_opportunity_202001231041].[stage].&[Qualify Opportunity]") -> 1284500 | R26: Vinay | S26: 5 | U26: Raju Kumar | V26: 2
D27: for VLOOKUP | E27: Animesh Rawat | G27: Shivani Sharma | H27: 4 | L27: Gilbert | M27: 386738.25 | N27: Shivani Sharma | O27: Shivani Sharma | R27: Grand Total | S27: 34 | U27: Mark | V27: 2
E28: Gilbert | G28: Vinay | H28: 5 | L28: Juli | M28: 149485.39 | N28: Shivani Sharma | O28: Qualify Opportunity | P28: 1325000
A29: Row Labels | B29: Count of stage | C29: Table 6 | E29: Juli | G29: Grand Total | H29: 34 | L29: Ketan Jain | M29: 369095.49 | N29: Vinay | O29: Vinay
A30: Negotiate | E30: Ketan Jain | L30: Kumar Jha | M30: 130049.5 | N30: Vinay | O30: Qualify Opportunity | P30: 755000 | Q30: =GETPIVOTDATA("[Measures].[Sum of revenue_amount]",$O$17,"[gcrm_opportunity_202001231041].[Account Executive]","[gcrm_opportunity_202001231041].[Account Executive].&[Vinay]","[gcrm_opportunity_202001231041].[stage]","[gcrm_opportunity_202001231041].[stage].&[Qualify Opportunity]") -> 755000
A31: Animesh Rawat | B31: 3 | E31: Kumar Jha | L31: Manish Sharma | M31: 29928.34 | O31: Grand Total | P31: 6878500
A32: Mark | B32: 2 | E32: Manish Sharma | L32: Mark | M32: 5061503.2 | O32: Employee funnel chart
A33: Propose Solution | E33: Mark | L33: Raju Kumar | M33: 452577.19 | O33: Row Labels | P33: Sum of revenue_amount
A34: Animesh Rawat | B34: 2 | E34: Nishant Sharma | L34: Shivani Sharma | M34: 888648.86 | O34: Animesh Rawat | Q34: =O34 -> Animesh Rawat
A35: Qualify Opportunity | E35: Raju Kumar | L35: Vididt Saha | M35: 144957.51 | O35: Negotiate | P35: 800000 | Q35: Qualify Opportunity | R35: =VLOOKUP(Q35,O35:P37,2,0) -> 1025000
A36: Animesh Rawat | B36: 5 | E36: Shivani Sharma | L36: Vinay | M36: 4338831.7 | O36: Propose Solution | P36: 60000 | Q36: =O35 -> Negotiate | R36: =VLOOKUP(Q36,O34:P36,2,0) -> 800000
A37: Ketan Jain | B37: 9 | E37: Vididt Saha | L37: Grand Total | M37: 33376569 | O37: Qualify Opportunity | P37: 1025000 | Q37: =O36 -> Propose Solution | R37: =VLOOKUP(Q37,O35:P37,2,0) -> 60000
A38: Mark | B38: 9 | E38: Vinay | O38: Ketan Jain
A39: Shivani Sharma | B39: 11 | E39: (blank) | O39: Qualify Opportunity | P39: 1530000
A40: Vinay | B40: 8 | E40: Grand Total | O40: Mark
...

Sheet Notes
B2: In invoice box for below given employees saw values even though same not have any data in invoice data.
B3: Shivanu sharma
B4: Raju
B5: Manish sharma
B7: Hence, used ISBLANK function to deal with this issue.
B9: In case we replace whole data from connected table then need to ensure that new data headers matching with previous one.
B10: If updated header will not match with previous header name pivot table will not be updated with latest data.

Sheet Links
B3: http://youtube.com/watch?v=a2A_gBTkUcU
